test_even (exercise_tests.ExerciseTests) ... ok
test_odd (exercise_tests.ExerciseTests) ... FAIL

======================================================================
FAIL: test_odd (exercise_tests.ExerciseTests)
----------------------------------------------------------------------
Traceback (most recent call last):
  File "/workspace/exercise_tests.py", line 13, in test_odd
    self.assertTrue(odd(x))
AssertionError: 0 is not true

----------------------------------------------------------------------
Ran 2 tests in 0.000s

FAILED (failures=1)
